{"cells":[{"cell_type":"code","execution_count":1,"metadata":{"colab":{"base_uri":"https://localhost:8080/"},"executionInfo":{"elapsed":3542,"status":"ok","timestamp":1682924905172,"user":{"displayName":"김영현","userId":"01553223046875508315"},"user_tz":-540},"id":"9MAqay7DHVNm","outputId":"4508510f-b1e3-471d-9b90-8f47e8c0eb7e"},"outputs":[{"name":"stdout","output_type":"stream","text":["Drive already mounted at /content/drive; to attempt to forcibly remount, call drive.mount(\"/content/drive\", force_remount=True).\n"]}],"source":["from google.colab import drive\n","drive.mount('/content/drive')"]},{"cell_type":"code","execution_count":2,"metadata":{"colab":{"base_uri":"https://localhost:8080/"},"executionInfo":{"elapsed":13,"status":"ok","timestamp":1682924905174,"user":{"displayName":"김영현","userId":"01553223046875508315"},"user_tz":-540},"id":"EzJNARfwHlaC","outputId":"443b39ce-503e-448e-f5a9-e64bd62716b0"},"outputs":[{"name":"stdout","output_type":"stream","text":["/content/drive/MyDrive/rich/main/rich\n"]}],"source":["cd drive/MyDrive/rich/main/rich/"]},{"cell_type":"code","execution_count":3,"metadata":{"colab":{"base_uri":"https://localhost:8080/"},"executionInfo":{"elapsed":2876,"status":"ok","timestamp":1682924908041,"user":{"displayName":"김영현","userId":"01553223046875508315"},"user_tz":-540},"id":"ABjoqcl7HsD0","outputId":"30580960-5a2b-4c2d-c28e-6f53b2ae5cdd"},"outputs":[{"name":"stdout","output_type":"stream","text":["Looking in indexes: https://pypi.org/simple, https://us-python.pkg.dev/colab-wheels/public/simple/\n","Requirement already satisfied: tensorboardX in /usr/local/lib/python3.10/dist-packages (2.6)\n","Requirement already satisfied: packaging in /usr/local/lib/python3.10/dist-packages (from tensorboardX) (23.1)\n","Requirement already satisfied: protobuf\u003c4,\u003e=3.8.0 in /usr/local/lib/python3.10/dist-packages (from tensorboardX) (3.20.3)\n","Requirement already satisfied: numpy in /usr/local/lib/python3.10/dist-packages (from tensorboardX) (1.22.4)\n"]}],"source":["!pip install tensorboardX"]},{"cell_type":"code","execution_count":4,"metadata":{"colab":{"base_uri":"https://localhost:8080/"},"executionInfo":{"elapsed":4102,"status":"ok","timestamp":1682924912136,"user":{"displayName":"김영현","userId":"01553223046875508315"},"user_tz":-540},"id":"JJGoba9y17Lj","outputId":"e56ddc9e-45f7-44af-aa6b-1e8d995e3244"},"outputs":[{"name":"stdout","output_type":"stream","text":["Looking in indexes: https://pypi.org/simple, https://us-python.pkg.dev/colab-wheels/public/simple/\n","Requirement already satisfied: ray in /usr/local/lib/python3.10/dist-packages (2.4.0)\n","Requirement already satisfied: aiosignal in /usr/local/lib/python3.10/dist-packages (from ray) (1.3.1)\n","Requirement already satisfied: protobuf!=3.19.5,\u003e=3.15.3 in /usr/local/lib/python3.10/dist-packages (from ray) (3.20.3)\n","Requirement already satisfied: frozenlist in /usr/local/lib/python3.10/dist-packages (from ray) (1.3.3)\n","Requirement already satisfied: numpy\u003e=1.19.3 in /usr/local/lib/python3.10/dist-packages (from ray) (1.22.4)\n","Requirement already satisfied: jsonschema in /usr/local/lib/python3.10/dist-packages (from ray) (4.3.3)\n","Requirement already satisfied: virtualenv\u003c20.21.1,\u003e=20.0.24 in /usr/local/lib/python3.10/dist-packages (from ray) (20.21.0)\n","Requirement already satisfied: pyyaml in /usr/local/lib/python3.10/dist-packages (from ray) (6.0)\n","Requirement already satisfied: packaging in /usr/local/lib/python3.10/dist-packages (from ray) (23.1)\n","Requirement already satisfied: grpcio\u003c=1.51.3,\u003e=1.42.0 in /usr/local/lib/python3.10/dist-packages (from ray) (1.51.3)\n","Requirement already satisfied: click\u003e=7.0 in /usr/local/lib/python3.10/dist-packages (from ray) (8.1.3)\n","Requirement already satisfied: attrs in /usr/local/lib/python3.10/dist-packages (from ray) (23.1.0)\n","Requirement already satisfied: requests in /usr/local/lib/python3.10/dist-packages (from ray) (2.27.1)\n","Requirement already satisfied: msgpack\u003c2.0.0,\u003e=1.0.0 in /usr/local/lib/python3.10/dist-packages (from ray) (1.0.5)\n","Requirement already satisfied: filelock in /usr/local/lib/python3.10/dist-packages (from ray) (3.12.0)\n","Requirement already satisfied: platformdirs\u003c4,\u003e=2.4 in /usr/local/lib/python3.10/dist-packages (from virtualenv\u003c20.21.1,\u003e=20.0.24-\u003eray) (3.3.0)\n","Requirement already satisfied: distlib\u003c1,\u003e=0.3.6 in /usr/local/lib/python3.10/dist-packages (from virtualenv\u003c20.21.1,\u003e=20.0.24-\u003eray) (0.3.6)\n","Requirement already satisfied: pyrsistent!=0.17.0,!=0.17.1,!=0.17.2,\u003e=0.14.0 in /usr/local/lib/python3.10/dist-packages (from jsonschema-\u003eray) (0.19.3)\n","Requirement already satisfied: urllib3\u003c1.27,\u003e=1.21.1 in /usr/local/lib/python3.10/dist-packages (from requests-\u003eray) (1.26.15)\n","Requirement already satisfied: charset-normalizer~=2.0.0 in /usr/local/lib/python3.10/dist-packages (from requests-\u003eray) (2.0.12)\n","Requirement already satisfied: idna\u003c4,\u003e=2.5 in /usr/local/lib/python3.10/dist-packages (from requests-\u003eray) (3.4)\n","Requirement already satisfied: certifi\u003e=2017.4.17 in /usr/local/lib/python3.10/dist-packages (from requests-\u003eray) (2022.12.7)\n"]}],"source":["!pip install ray"]},{"cell_type":"code","execution_count":null,"metadata":{"colab":{"background_save":true,"base_uri":"https://localhost:8080/"},"id":"qn3-dHi810Vy"},"outputs":[{"name":"stdout","output_type":"stream","text":["Simulation starts....\n","train_trader\n","/usr/local/lib/python3.10/dist-packages/torch/nn/modules/transformer.py:544: UserWarning: Converting mask without torch.bool dtype to bool; this will negatively affect performance. Prefer to use a boolean mask directly. (Triggered internally at ../aten/src/ATen/native/transformers/attention.cpp:150.)\n","  return torch._transformer_encoder_layer_fwd(\n","/content/drive/MyDrive/rich/main/rich/trained/trading_gpt_cl\n","20181228\n","train_trader\n","/content/drive/MyDrive/rich/main/rich/trained/trading_gpt_cl\n","20190129\n","train_trader\n","/content/drive/MyDrive/rich/main/rich/trained/trading_gpt_cl\n","20190304\n","train_trader\n","/content/drive/MyDrive/rich/main/rich/trained/trading_gpt_cl\n","20190401\n","train_trader\n","/content/drive/MyDrive/rich/main/rich/trained/trading_gpt_cl\n","20190429\n","train_trader\n","/content/drive/MyDrive/rich/main/rich/trained/trading_gpt_cl\n","20190529\n","train_trader\n","/content/drive/MyDrive/rich/main/rich/trained/trading_gpt_cl\n","20190627\n","train_trader\n","/content/drive/MyDrive/rich/main/rich/trained/trading_gpt_cl\n","20190725\n","train_trader\n","/content/drive/MyDrive/rich/main/rich/trained/trading_gpt_cl\n","20190823\n","train_trader\n","/content/drive/MyDrive/rich/main/rich/trained/trading_gpt_cl\n","20190924\n","train_trader\n","/content/drive/MyDrive/rich/main/rich/trained/trading_gpt_cl\n","20191024\n","train_trader\n","/content/drive/MyDrive/rich/main/rich/trained/trading_gpt_cl\n","20191121\n","train_trader\n","/content/drive/MyDrive/rich/main/rich/trained/trading_gpt_cl\n","20191219\n","train_trader\n","/content/drive/MyDrive/rich/main/rich/trained/trading_gpt_cl\n","20200121\n","train_trader\n","/content/drive/MyDrive/rich/main/rich/trained/trading_gpt_cl\n","20200220\n","train_trader\n","/content/drive/MyDrive/rich/main/rich/trained/trading_gpt_cl\n","20200319\n","train_trader\n","/content/drive/MyDrive/rich/main/rich/trained/trading_gpt_cl\n","20200417\n","train_trader\n","/content/drive/MyDrive/rich/main/rich/trained/trading_gpt_cl\n","20200520\n","train_trader\n","/content/drive/MyDrive/rich/main/rich/trained/trading_gpt_cl\n","20200617\n","train_trader\n","/content/drive/MyDrive/rich/main/rich/trained/trading_gpt_cl\n","20200715\n","train_trader\n","/content/drive/MyDrive/rich/main/rich/trained/trading_gpt_cl\n","20200812\n","train_trader\n","/content/drive/MyDrive/rich/main/rich/trained/trading_gpt_cl\n","20200910\n","train_trader\n","/content/drive/MyDrive/rich/main/rich/trained/trading_gpt_cl\n","20201014\n","train_trader\n","/content/drive/MyDrive/rich/main/rich/trained/trading_gpt_cl\n","20201111\n","train_trader\n","/content/drive/MyDrive/rich/main/rich/trained/trading_gpt_cl\n","20201209\n","train_trader\n","/content/drive/MyDrive/rich/main/rich/trained/trading_gpt_cl\n","20210111\n","train_trader\n","/content/drive/MyDrive/rich/main/rich/trained/trading_gpt_cl\n","20210208\n","train_trader\n","/content/drive/MyDrive/rich/main/rich/trained/trading_gpt_cl\n","20210311\n","train_trader\n","/content/drive/MyDrive/rich/main/rich/trained/trading_gpt_cl\n","20210408\n","train_trader\n","/content/drive/MyDrive/rich/main/rich/trained/trading_gpt_cl\n","20210507\n","train_trader\n","/content/drive/MyDrive/rich/main/rich/trained/trading_gpt_cl\n","20210607\n","train_trader\n","/content/drive/MyDrive/rich/main/rich/trained/trading_gpt_cl\n","20210705\n","train_trader\n","/content/drive/MyDrive/rich/main/rich/trained/trading_gpt_cl\n","20210802\n","train_trader\n","/content/drive/MyDrive/rich/main/rich/trained/trading_gpt_cl\n","20210831\n","train_trader\n","/content/drive/MyDrive/rich/main/rich/trained/trading_gpt_cl\n","20211001\n","train_trader\n","/content/drive/MyDrive/rich/main/rich/trained/trading_gpt_cl\n","20211102\n","train_trader\n","/content/drive/MyDrive/rich/main/rich/trained/trading_gpt_cl\n","20211130\n","train_trader\n","/content/drive/MyDrive/rich/main/rich/trained/trading_gpt_cl\n","20211228\n","train_trader\n","/content/drive/MyDrive/rich/main/rich/trained/trading_gpt_cl\n","20220126\n","train_trader\n","/content/drive/MyDrive/rich/main/rich/trained/trading_gpt_cl\n","20220228\n","train_trader\n","/content/drive/MyDrive/rich/main/rich/trained/trading_gpt_cl\n","20220330\n","train_trader\n","/content/drive/MyDrive/rich/main/rich/trained/trading_gpt_cl\n","20220427\n","train_trader\n","/content/drive/MyDrive/rich/main/rich/trained/trading_gpt_cl\n","20220526\n","train_trader\n","/content/drive/MyDrive/rich/main/rich/trained/trading_gpt_cl\n","20220627\n","train_trader\n","/content/drive/MyDrive/rich/main/rich/trained/trading_gpt_cl\n","20220725\n","train_trader\n","/content/drive/MyDrive/rich/main/rich/trained/trading_gpt_cl\n","20220823\n","train_trader\n","/content/drive/MyDrive/rich/main/rich/trained/trading_gpt_cl\n","20220922\n","train_trader\n","/content/drive/MyDrive/rich/main/rich/trained/trading_gpt_cl\n","20221024\n","train_trader\n","/content/drive/MyDrive/rich/main/rich/trained/trading_gpt_cl\n","20221121\n","train_trader\n","/content/drive/MyDrive/rich/main/rich/trained/trading_gpt_cl\n","20221219\n","train_trader\n","/content/drive/MyDrive/rich/main/rich/trained/trading_gpt_cl\n","20230117\n","train_trader\n","/content/drive/MyDrive/rich/main/rich/trained/trading_gpt_cl\n","20230216\n","train_trader\n","/content/drive/MyDrive/rich/main/rich/trained/trading_gpt_cl\n","20230317\n","train_trader\n","/content/drive/MyDrive/rich/main/rich/trained/trading_gpt_cl\n","20230414\n","\u001b[0m"]}],"source":["!PYTHONPATH=./ python trainers/trading_gpt_train_cl.py --epoch_size=50 --num_samples 1\\\n"," --batch_size 128 --device cuda --lr 0.00001 --model_cl_name trading_gpt_cl"]},{"cell_type":"code","execution_count":null,"metadata":{"colab":{"background_save":true},"id":"U2Um-foK3fzv"},"outputs":[{"name":"stdout","output_type":"stream","text":["shell-init: error retrieving current directory: getcwd: cannot access parent directories: Transport endpoint is not connected\n","Mon May  1 19:54:51 2023       \n","+-----------------------------------------------------------------------------+\n","| NVIDIA-SMI 525.85.12    Driver Version: 525.85.12    CUDA Version: 12.0     |\n","|-------------------------------+----------------------+----------------------+\n","| GPU  Name        Persistence-M| Bus-Id        Disp.A | Volatile Uncorr. ECC |\n","| Fan  Temp  Perf  Pwr:Usage/Cap|         Memory-Usage | GPU-Util  Compute M. |\n","|                               |                      |               MIG M. |\n","|===============================+======================+======================|\n","|   0  NVIDIA A100-SXM...  Off  | 00000000:00:04.0 Off |                    0 |\n","| N/A   39C    P0    55W / 400W |      0MiB / 40960MiB |     25%      Default |\n","|                               |                      |             Disabled |\n","+-------------------------------+----------------------+----------------------+\n","                                                                               \n","+-----------------------------------------------------------------------------+\n","| Processes:                                                                  |\n","|  GPU   GI   CI        PID   Type   Process name                  GPU Memory |\n","|        ID   ID                                                   Usage      |\n","|=============================================================================|\n","|  No running processes found                                                 |\n","+-----------------------------------------------------------------------------+\n"]}],"source":["!nvidia-smi"]},{"cell_type":"code","execution_count":null,"metadata":{"colab":{"background_save":true},"id":"kZ9XzRz-uFw2"},"outputs":[{"name":"stderr","output_type":"stream","text":["ERROR:root:Internal Python error in the inspect module.\n","Below is the traceback from this internal error.\n","\n","ERROR:root:Internal Python error in the inspect module.\n","Below is the traceback from this internal error.\n","\n","ERROR:root:Internal Python error in the inspect module.\n","Below is the traceback from this internal error.\n","\n"]},{"name":"stdout","output_type":"stream","text":["Traceback (most recent call last):\n","  File \"/usr/local/lib/python3.10/dist-packages/IPython/core/interactiveshell.py\", line 3553, in run_code\n","    exec(code_obj, self.user_global_ns, self.user_ns)\n","  File \"\u003cipython-input-7-eb42ca6e4af3\u003e\", line 1, in \u003ccell line: 1\u003e\n","    import torch\n","  File \"\u003cfrozen importlib._bootstrap\u003e\", line 1027, in _find_and_load\n","  File \"\u003cfrozen importlib._bootstrap\u003e\", line 1002, in _find_and_load_unlocked\n","  File \"\u003cfrozen importlib._bootstrap\u003e\", line 945, in _find_spec\n","  File \"\u003cfrozen importlib._bootstrap_external\u003e\", line 1439, in find_spec\n","  File \"\u003cfrozen importlib._bootstrap_external\u003e\", line 1408, in _get_spec\n","  File \"\u003cfrozen importlib._bootstrap_external\u003e\", line 1366, in _path_importer_cache\n","OSError: [Errno 107] Transport endpoint is not connected\n","\n","During handling of the above exception, another exception occurred:\n","\n","Traceback (most recent call last):\n","  File \"/usr/local/lib/python3.10/dist-packages/IPython/core/interactiveshell.py\", line 2099, in showtraceback\n","    stb = value._render_traceback_()\n","AttributeError: 'OSError' object has no attribute '_render_traceback_'\n","\n","During handling of the above exception, another exception occurred:\n","\n","Traceback (most recent call last):\n","  File \"/usr/local/lib/python3.10/dist-packages/IPython/core/ultratb.py\", line 1101, in get_records\n","    return _fixed_getinnerframes(etb, number_of_lines_of_context, tb_offset)\n","  File \"/usr/local/lib/python3.10/dist-packages/IPython/core/ultratb.py\", line 248, in wrapped\n","    return f(*args, **kwargs)\n","  File \"/usr/local/lib/python3.10/dist-packages/IPython/core/ultratb.py\", line 281, in _fixed_getinnerframes\n","    records = fix_frame_records_filenames(inspect.getinnerframes(etb, context))\n","  File \"/usr/lib/python3.10/inspect.py\", line 1662, in getinnerframes\n","    frameinfo = (tb.tb_frame,) + getframeinfo(tb, context)\n","  File \"/usr/lib/python3.10/inspect.py\", line 1620, in getframeinfo\n","    filename = getsourcefile(frame) or getfile(frame)\n","  File \"/usr/lib/python3.10/inspect.py\", line 829, in getsourcefile\n","    module = getmodule(object, filename)\n","  File \"/usr/lib/python3.10/inspect.py\", line 861, in getmodule\n","    file = getabsfile(object, _filename)\n","  File \"/usr/lib/python3.10/inspect.py\", line 845, in getabsfile\n","    return os.path.normcase(os.path.abspath(_filename))\n","  File \"/usr/lib/python3.10/posixpath.py\", line 384, in abspath\n","    cwd = os.getcwd()\n","OSError: [Errno 107] Transport endpoint is not connected\n","Traceback (most recent call last):\n","  File \"/usr/local/lib/python3.10/dist-packages/IPython/core/interactiveshell.py\", line 3553, in run_code\n","    exec(code_obj, self.user_global_ns, self.user_ns)\n","  File \"\u003cipython-input-7-eb42ca6e4af3\u003e\", line 1, in \u003ccell line: 1\u003e\n","    import torch\n","  File \"\u003cfrozen importlib._bootstrap\u003e\", line 1027, in _find_and_load\n","  File \"\u003cfrozen importlib._bootstrap\u003e\", line 1002, in _find_and_load_unlocked\n","  File \"\u003cfrozen importlib._bootstrap\u003e\", line 945, in _find_spec\n","  File \"\u003cfrozen importlib._bootstrap_external\u003e\", line 1439, in find_spec\n","  File \"\u003cfrozen importlib._bootstrap_external\u003e\", line 1408, in _get_spec\n","  File \"\u003cfrozen importlib._bootstrap_external\u003e\", line 1366, in _path_importer_cache\n","OSError: [Errno 107] Transport endpoint is not connected\n","\n","During handling of the above exception, another exception occurred:\n","\n","Traceback (most recent call last):\n","  File \"/usr/local/lib/python3.10/dist-packages/IPython/core/interactiveshell.py\", line 2099, in showtraceback\n","    stb = value._render_traceback_()\n","AttributeError: 'OSError' object has no attribute '_render_traceback_'\n","\n","During handling of the above exception, another exception occurred:\n","\n","Traceback (most recent call last):\n","  File \"/usr/local/lib/python3.10/dist-packages/IPython/core/interactiveshell.py\", line 3473, in run_ast_nodes\n","    if (await self.run_code(code, result,  async_=asy)):\n","  File \"/usr/local/lib/python3.10/dist-packages/IPython/core/interactiveshell.py\", line 3575, in run_code\n","    self.showtraceback(running_compiled_code=True)\n","  File \"/usr/local/lib/python3.10/dist-packages/IPython/core/interactiveshell.py\", line 2101, in showtraceback\n","    stb = self.InteractiveTB.structured_traceback(etype,\n","  File \"/usr/local/lib/python3.10/dist-packages/IPython/core/ultratb.py\", line 1367, in structured_traceback\n","    return FormattedTB.structured_traceback(\n","  File \"/usr/local/lib/python3.10/dist-packages/IPython/core/ultratb.py\", line 1267, in structured_traceback\n","    return VerboseTB.structured_traceback(\n","  File \"/usr/local/lib/python3.10/dist-packages/IPython/core/ultratb.py\", line 1124, in structured_traceback\n","    formatted_exception = self.format_exception_as_a_whole(etype, evalue, etb, number_of_lines_of_context,\n","  File \"/usr/local/lib/python3.10/dist-packages/IPython/core/ultratb.py\", line 1082, in format_exception_as_a_whole\n","    last_unique, recursion_repeat = find_recursion(orig_etype, evalue, records)\n","  File \"/usr/local/lib/python3.10/dist-packages/IPython/core/ultratb.py\", line 382, in find_recursion\n","    return len(records), 0\n","TypeError: object of type 'NoneType' has no len()\n","\n","During handling of the above exception, another exception occurred:\n","\n","Traceback (most recent call last):\n","  File \"/usr/local/lib/python3.10/dist-packages/IPython/core/interactiveshell.py\", line 2099, in showtraceback\n","    stb = value._render_traceback_()\n","AttributeError: 'TypeError' object has no attribute '_render_traceback_'\n","\n","During handling of the above exception, another exception occurred:\n","\n","Traceback (most recent call last):\n","  File \"/usr/local/lib/python3.10/dist-packages/IPython/core/ultratb.py\", line 1101, in get_records\n","    return _fixed_getinnerframes(etb, number_of_lines_of_context, tb_offset)\n","  File \"/usr/local/lib/python3.10/dist-packages/IPython/core/ultratb.py\", line 248, in wrapped\n","    return f(*args, **kwargs)\n","  File \"/usr/local/lib/python3.10/dist-packages/IPython/core/ultratb.py\", line 281, in _fixed_getinnerframes\n","    records = fix_frame_records_filenames(inspect.getinnerframes(etb, context))\n","  File \"/usr/lib/python3.10/inspect.py\", line 1662, in getinnerframes\n","    frameinfo = (tb.tb_frame,) + getframeinfo(tb, context)\n","  File \"/usr/lib/python3.10/inspect.py\", line 1620, in getframeinfo\n","    filename = getsourcefile(frame) or getfile(frame)\n","  File \"/usr/lib/python3.10/inspect.py\", line 829, in getsourcefile\n","    module = getmodule(object, filename)\n","  File \"/usr/lib/python3.10/inspect.py\", line 861, in getmodule\n","    file = getabsfile(object, _filename)\n","  File \"/usr/lib/python3.10/inspect.py\", line 845, in getabsfile\n","    return os.path.normcase(os.path.abspath(_filename))\n","  File \"/usr/lib/python3.10/posixpath.py\", line 384, in abspath\n","    cwd = os.getcwd()\n","OSError: [Errno 107] Transport endpoint is not connected\n","Traceback (most recent call last):\n","  File \"/usr/local/lib/python3.10/dist-packages/IPython/core/interactiveshell.py\", line 3553, in run_code\n","    exec(code_obj, self.user_global_ns, self.user_ns)\n","  File \"\u003cipython-input-7-eb42ca6e4af3\u003e\", line 1, in \u003ccell line: 1\u003e\n","    import torch\n","  File \"\u003cfrozen importlib._bootstrap\u003e\", line 1027, in _find_and_load\n","  File \"\u003cfrozen importlib._bootstrap\u003e\", line 1002, in _find_and_load_unlocked\n","  File \"\u003cfrozen importlib._bootstrap\u003e\", line 945, in _find_spec\n","  File \"\u003cfrozen importlib._bootstrap_external\u003e\", line 1439, in find_spec\n","  File \"\u003cfrozen importlib._bootstrap_external\u003e\", line 1408, in _get_spec\n","  File \"\u003cfrozen importlib._bootstrap_external\u003e\", line 1366, in _path_importer_cache\n","OSError: [Errno 107] Transport endpoint is not connected\n","\n","During handling of the above exception, another exception occurred:\n","\n","Traceback (most recent call last):\n","  File \"/usr/local/lib/python3.10/dist-packages/IPython/core/interactiveshell.py\", line 2099, in showtraceback\n","    stb = value._render_traceback_()\n","AttributeError: 'OSError' object has no attribute '_render_traceback_'\n","\n","During handling of the above exception, another exception occurred:\n","\n","Traceback (most recent call last):\n","  File \"/usr/local/lib/python3.10/dist-packages/IPython/core/interactiveshell.py\", line 3473, in run_ast_nodes\n","    if (await self.run_code(code, result,  async_=asy)):\n","  File \"/usr/local/lib/python3.10/dist-packages/IPython/core/interactiveshell.py\", line 3575, in run_code\n","    self.showtraceback(running_compiled_code=True)\n","  File \"/usr/local/lib/python3.10/dist-packages/IPython/core/interactiveshell.py\", line 2101, in showtraceback\n","    stb = self.InteractiveTB.structured_traceback(etype,\n","  File \"/usr/local/lib/python3.10/dist-packages/IPython/core/ultratb.py\", line 1367, in structured_traceback\n","    return FormattedTB.structured_traceback(\n","  File \"/usr/local/lib/python3.10/dist-packages/IPython/core/ultratb.py\", line 1267, in structured_traceback\n","    return VerboseTB.structured_traceback(\n","  File \"/usr/local/lib/python3.10/dist-packages/IPython/core/ultratb.py\", line 1124, in structured_traceback\n","    formatted_exception = self.format_exception_as_a_whole(etype, evalue, etb, number_of_lines_of_context,\n","  File \"/usr/local/lib/python3.10/dist-packages/IPython/core/ultratb.py\", line 1082, in format_exception_as_a_whole\n","    last_unique, recursion_repeat = find_recursion(orig_etype, evalue, records)\n","  File \"/usr/local/lib/python3.10/dist-packages/IPython/core/ultratb.py\", line 382, in find_recursion\n","    return len(records), 0\n","TypeError: object of type 'NoneType' has no len()\n","\n","During handling of the above exception, another exception occurred:\n","\n","Traceback (most recent call last):\n","  File \"/usr/local/lib/python3.10/dist-packages/IPython/core/interactiveshell.py\", line 2099, in showtraceback\n","    stb = value._render_traceback_()\n","AttributeError: 'TypeError' object has no attribute '_render_traceback_'\n","\n","During handling of the above exception, another exception occurred:\n","\n","Traceback (most recent call last):\n","  File \"/usr/local/lib/python3.10/dist-packages/IPython/core/interactiveshell.py\", line 3030, in _run_cell\n","    return runner(coro)\n","  File \"/usr/local/lib/python3.10/dist-packages/IPython/core/async_helpers.py\", line 78, in _pseudo_sync_runner\n","    coro.send(None)\n","  File \"/usr/local/lib/python3.10/dist-packages/IPython/core/interactiveshell.py\", line 3257, in run_cell_async\n","    has_raised = await self.run_ast_nodes(code_ast.body, cell_name,\n","  File \"/usr/local/lib/python3.10/dist-packages/IPython/core/interactiveshell.py\", line 3492, in run_ast_nodes\n","    self.showtraceback()\n","  File \"/usr/local/lib/python3.10/dist-packages/IPython/core/interactiveshell.py\", line 2101, in showtraceback\n","    stb = self.InteractiveTB.structured_traceback(etype,\n","  File \"/usr/local/lib/python3.10/dist-packages/IPython/core/ultratb.py\", line 1367, in structured_traceback\n","    return FormattedTB.structured_traceback(\n","  File \"/usr/local/lib/python3.10/dist-packages/IPython/core/ultratb.py\", line 1267, in structured_traceback\n","    return VerboseTB.structured_traceback(\n","  File \"/usr/local/lib/python3.10/dist-packages/IPython/core/ultratb.py\", line 1142, in structured_traceback\n","    formatted_exceptions += self.format_exception_as_a_whole(etype, evalue, etb, lines_of_context,\n","  File \"/usr/local/lib/python3.10/dist-packages/IPython/core/ultratb.py\", line 1082, in format_exception_as_a_whole\n","    last_unique, recursion_repeat = find_recursion(orig_etype, evalue, records)\n","  File \"/usr/local/lib/python3.10/dist-packages/IPython/core/ultratb.py\", line 382, in find_recursion\n","    return len(records), 0\n","TypeError: object of type 'NoneType' has no len()\n","\n","During handling of the above exception, another exception occurred:\n","\n","Traceback (most recent call last):\n","  File \"/usr/local/lib/python3.10/dist-packages/IPython/core/interactiveshell.py\", line 2099, in showtraceback\n","    stb = value._render_traceback_()\n","AttributeError: 'TypeError' object has no attribute '_render_traceback_'\n","\n","During handling of the above exception, another exception occurred:\n","\n","Traceback (most recent call last):\n","  File \"/usr/local/lib/python3.10/dist-packages/IPython/core/ultratb.py\", line 1101, in get_records\n","    return _fixed_getinnerframes(etb, number_of_lines_of_context, tb_offset)\n","  File \"/usr/local/lib/python3.10/dist-packages/IPython/core/ultratb.py\", line 248, in wrapped\n","    return f(*args, **kwargs)\n","  File \"/usr/local/lib/python3.10/dist-packages/IPython/core/ultratb.py\", line 281, in _fixed_getinnerframes\n","    records = fix_frame_records_filenames(inspect.getinnerframes(etb, context))\n","  File \"/usr/lib/python3.10/inspect.py\", line 1662, in getinnerframes\n","    frameinfo = (tb.tb_frame,) + getframeinfo(tb, context)\n","  File \"/usr/lib/python3.10/inspect.py\", line 1620, in getframeinfo\n","    filename = getsourcefile(frame) or getfile(frame)\n","  File \"/usr/lib/python3.10/inspect.py\", line 829, in getsourcefile\n","    module = getmodule(object, filename)\n","  File \"/usr/lib/python3.10/inspect.py\", line 861, in getmodule\n","    file = getabsfile(object, _filename)\n","  File \"/usr/lib/python3.10/inspect.py\", line 845, in getabsfile\n","    return os.path.normcase(os.path.abspath(_filename))\n","  File \"/usr/lib/python3.10/posixpath.py\", line 384, in abspath\n","    cwd = os.getcwd()\n","OSError: [Errno 107] Transport endpoint is not connected\n"]}],"source":["import torch"]},{"cell_type":"code","execution_count":null,"metadata":{"colab":{"background_save":true},"id":"IqqFizKquIhw"},"outputs":[{"name":"stderr","output_type":"stream","text":["ERROR:root:Internal Python error in the inspect module.\n","Below is the traceback from this internal error.\n","\n","ERROR:root:Internal Python error in the inspect module.\n","Below is the traceback from this internal error.\n","\n"]},{"name":"stdout","output_type":"stream","text":["Traceback (most recent call last):\n","  File \"/usr/local/lib/python3.10/dist-packages/IPython/core/interactiveshell.py\", line 3553, in run_code\n","    exec(code_obj, self.user_global_ns, self.user_ns)\n","  File \"\u003cipython-input-7-ec9450a707b2\u003e\", line 1, in \u003ccell line: 1\u003e\n","    torch.__version__\n","NameError: name 'torch' is not defined\n","\n","During handling of the above exception, another exception occurred:\n","\n","Traceback (most recent call last):\n","  File \"/usr/local/lib/python3.10/dist-packages/IPython/core/interactiveshell.py\", line 2099, in showtraceback\n","    stb = value._render_traceback_()\n","AttributeError: 'NameError' object has no attribute '_render_traceback_'\n","\n","During handling of the above exception, another exception occurred:\n","\n","Traceback (most recent call last):\n","  File \"/usr/local/lib/python3.10/dist-packages/IPython/core/ultratb.py\", line 1101, in get_records\n","    return _fixed_getinnerframes(etb, number_of_lines_of_context, tb_offset)\n","  File \"/usr/local/lib/python3.10/dist-packages/IPython/core/ultratb.py\", line 248, in wrapped\n","    return f(*args, **kwargs)\n","  File \"/usr/local/lib/python3.10/dist-packages/IPython/core/ultratb.py\", line 281, in _fixed_getinnerframes\n","    records = fix_frame_records_filenames(inspect.getinnerframes(etb, context))\n","  File \"/usr/lib/python3.10/inspect.py\", line 1662, in getinnerframes\n","    frameinfo = (tb.tb_frame,) + getframeinfo(tb, context)\n","  File \"/usr/lib/python3.10/inspect.py\", line 1620, in getframeinfo\n","    filename = getsourcefile(frame) or getfile(frame)\n","  File \"/usr/lib/python3.10/inspect.py\", line 829, in getsourcefile\n","    module = getmodule(object, filename)\n","  File \"/usr/lib/python3.10/inspect.py\", line 861, in getmodule\n","    file = getabsfile(object, _filename)\n","  File \"/usr/lib/python3.10/inspect.py\", line 845, in getabsfile\n","    return os.path.normcase(os.path.abspath(_filename))\n","  File \"/usr/lib/python3.10/posixpath.py\", line 384, in abspath\n","    cwd = os.getcwd()\n","OSError: [Errno 107] Transport endpoint is not connected\n","Traceback (most recent call last):\n","  File \"/usr/local/lib/python3.10/dist-packages/IPython/core/interactiveshell.py\", line 3553, in run_code\n","    exec(code_obj, self.user_global_ns, self.user_ns)\n","  File \"\u003cipython-input-7-ec9450a707b2\u003e\", line 1, in \u003ccell line: 1\u003e\n","    torch.__version__\n","NameError: name 'torch' is not defined\n","\n","During handling of the above exception, another exception occurred:\n","\n","Traceback (most recent call last):\n","  File \"/usr/local/lib/python3.10/dist-packages/IPython/core/interactiveshell.py\", line 2099, in showtraceback\n","    stb = value._render_traceback_()\n","AttributeError: 'NameError' object has no attribute '_render_traceback_'\n","\n","During handling of the above exception, another exception occurred:\n","\n","Traceback (most recent call last):\n","  File \"/usr/local/lib/python3.10/dist-packages/IPython/core/interactiveshell.py\", line 3473, in run_ast_nodes\n","    if (await self.run_code(code, result,  async_=asy)):\n","  File \"/usr/local/lib/python3.10/dist-packages/IPython/core/interactiveshell.py\", line 3575, in run_code\n","    self.showtraceback(running_compiled_code=True)\n","  File \"/usr/local/lib/python3.10/dist-packages/IPython/core/interactiveshell.py\", line 2101, in showtraceback\n","    stb = self.InteractiveTB.structured_traceback(etype,\n","  File \"/usr/local/lib/python3.10/dist-packages/IPython/core/ultratb.py\", line 1367, in structured_traceback\n","    return FormattedTB.structured_traceback(\n","  File \"/usr/local/lib/python3.10/dist-packages/IPython/core/ultratb.py\", line 1267, in structured_traceback\n","    return VerboseTB.structured_traceback(\n","  File \"/usr/local/lib/python3.10/dist-packages/IPython/core/ultratb.py\", line 1124, in structured_traceback\n","    formatted_exception = self.format_exception_as_a_whole(etype, evalue, etb, number_of_lines_of_context,\n","  File \"/usr/local/lib/python3.10/dist-packages/IPython/core/ultratb.py\", line 1082, in format_exception_as_a_whole\n","    last_unique, recursion_repeat = find_recursion(orig_etype, evalue, records)\n","  File \"/usr/local/lib/python3.10/dist-packages/IPython/core/ultratb.py\", line 382, in find_recursion\n","    return len(records), 0\n","TypeError: object of type 'NoneType' has no len()\n","\n","During handling of the above exception, another exception occurred:\n","\n","Traceback (most recent call last):\n","  File \"/usr/local/lib/python3.10/dist-packages/IPython/core/interactiveshell.py\", line 2099, in showtraceback\n","    stb = value._render_traceback_()\n","AttributeError: 'TypeError' object has no attribute '_render_traceback_'\n","\n","During handling of the above exception, another exception occurred:\n","\n","Traceback (most recent call last):\n","  File \"/usr/local/lib/python3.10/dist-packages/IPython/core/ultratb.py\", line 1101, in get_records\n","    return _fixed_getinnerframes(etb, number_of_lines_of_context, tb_offset)\n","  File \"/usr/local/lib/python3.10/dist-packages/IPython/core/ultratb.py\", line 248, in wrapped\n","    return f(*args, **kwargs)\n","  File \"/usr/local/lib/python3.10/dist-packages/IPython/core/ultratb.py\", line 281, in _fixed_getinnerframes\n","    records = fix_frame_records_filenames(inspect.getinnerframes(etb, context))\n","  File \"/usr/lib/python3.10/inspect.py\", line 1662, in getinnerframes\n","    frameinfo = (tb.tb_frame,) + getframeinfo(tb, context)\n","  File \"/usr/lib/python3.10/inspect.py\", line 1620, in getframeinfo\n","    filename = getsourcefile(frame) or getfile(frame)\n","  File \"/usr/lib/python3.10/inspect.py\", line 829, in getsourcefile\n","    module = getmodule(object, filename)\n","  File \"/usr/lib/python3.10/inspect.py\", line 861, in getmodule\n","    file = getabsfile(object, _filename)\n","  File \"/usr/lib/python3.10/inspect.py\", line 845, in getabsfile\n","    return os.path.normcase(os.path.abspath(_filename))\n","  File \"/usr/lib/python3.10/posixpath.py\", line 384, in abspath\n","    cwd = os.getcwd()\n","OSError: [Errno 107] Transport endpoint is not connected\n"]},{"name":"stderr","output_type":"stream","text":["ERROR:root:Internal Python error in the inspect module.\n","Below is the traceback from this internal error.\n","\n"]},{"name":"stdout","output_type":"stream","text":["Traceback (most recent call last):\n","  File \"/usr/local/lib/python3.10/dist-packages/IPython/core/interactiveshell.py\", line 3553, in run_code\n","    exec(code_obj, self.user_global_ns, self.user_ns)\n","  File \"\u003cipython-input-7-ec9450a707b2\u003e\", line 1, in \u003ccell line: 1\u003e\n","    torch.__version__\n","NameError: name 'torch' is not defined\n","\n","During handling of the above exception, another exception occurred:\n","\n","Traceback (most recent call last):\n","  File \"/usr/local/lib/python3.10/dist-packages/IPython/core/interactiveshell.py\", line 2099, in showtraceback\n","    stb = value._render_traceback_()\n","AttributeError: 'NameError' object has no attribute '_render_traceback_'\n","\n","During handling of the above exception, another exception occurred:\n","\n","Traceback (most recent call last):\n","  File \"/usr/local/lib/python3.10/dist-packages/IPython/core/interactiveshell.py\", line 3473, in run_ast_nodes\n","    if (await self.run_code(code, result,  async_=asy)):\n","  File \"/usr/local/lib/python3.10/dist-packages/IPython/core/interactiveshell.py\", line 3575, in run_code\n","    self.showtraceback(running_compiled_code=True)\n","  File \"/usr/local/lib/python3.10/dist-packages/IPython/core/interactiveshell.py\", line 2101, in showtraceback\n","    stb = self.InteractiveTB.structured_traceback(etype,\n","  File \"/usr/local/lib/python3.10/dist-packages/IPython/core/ultratb.py\", line 1367, in structured_traceback\n","    return FormattedTB.structured_traceback(\n","  File \"/usr/local/lib/python3.10/dist-packages/IPython/core/ultratb.py\", line 1267, in structured_traceback\n","    return VerboseTB.structured_traceback(\n","  File \"/usr/local/lib/python3.10/dist-packages/IPython/core/ultratb.py\", line 1124, in structured_traceback\n","    formatted_exception = self.format_exception_as_a_whole(etype, evalue, etb, number_of_lines_of_context,\n","  File \"/usr/local/lib/python3.10/dist-packages/IPython/core/ultratb.py\", line 1082, in format_exception_as_a_whole\n","    last_unique, recursion_repeat = find_recursion(orig_etype, evalue, records)\n","  File \"/usr/local/lib/python3.10/dist-packages/IPython/core/ultratb.py\", line 382, in find_recursion\n","    return len(records), 0\n","TypeError: object of type 'NoneType' has no len()\n","\n","During handling of the above exception, another exception occurred:\n","\n","Traceback (most recent call last):\n","  File \"/usr/local/lib/python3.10/dist-packages/IPython/core/interactiveshell.py\", line 2099, in showtraceback\n","    stb = value._render_traceback_()\n","AttributeError: 'TypeError' object has no attribute '_render_traceback_'\n","\n","During handling of the above exception, another exception occurred:\n","\n","Traceback (most recent call last):\n","  File \"/usr/local/lib/python3.10/dist-packages/IPython/core/interactiveshell.py\", line 3030, in _run_cell\n","    return runner(coro)\n","  File \"/usr/local/lib/python3.10/dist-packages/IPython/core/async_helpers.py\", line 78, in _pseudo_sync_runner\n","    coro.send(None)\n","  File \"/usr/local/lib/python3.10/dist-packages/IPython/core/interactiveshell.py\", line 3257, in run_cell_async\n","    has_raised = await self.run_ast_nodes(code_ast.body, cell_name,\n","  File \"/usr/local/lib/python3.10/dist-packages/IPython/core/interactiveshell.py\", line 3492, in run_ast_nodes\n","    self.showtraceback()\n","  File \"/usr/local/lib/python3.10/dist-packages/IPython/core/interactiveshell.py\", line 2101, in showtraceback\n","    stb = self.InteractiveTB.structured_traceback(etype,\n","  File \"/usr/local/lib/python3.10/dist-packages/IPython/core/ultratb.py\", line 1367, in structured_traceback\n","    return FormattedTB.structured_traceback(\n","  File \"/usr/local/lib/python3.10/dist-packages/IPython/core/ultratb.py\", line 1267, in structured_traceback\n","    return VerboseTB.structured_traceback(\n","  File \"/usr/local/lib/python3.10/dist-packages/IPython/core/ultratb.py\", line 1142, in structured_traceback\n","    formatted_exceptions += self.format_exception_as_a_whole(etype, evalue, etb, lines_of_context,\n","  File \"/usr/local/lib/python3.10/dist-packages/IPython/core/ultratb.py\", line 1082, in format_exception_as_a_whole\n","    last_unique, recursion_repeat = find_recursion(orig_etype, evalue, records)\n","  File \"/usr/local/lib/python3.10/dist-packages/IPython/core/ultratb.py\", line 382, in find_recursion\n","    return len(records), 0\n","TypeError: object of type 'NoneType' has no len()\n","\n","During handling of the above exception, another exception occurred:\n","\n","Traceback (most recent call last):\n","  File \"/usr/local/lib/python3.10/dist-packages/IPython/core/interactiveshell.py\", line 2099, in showtraceback\n","    stb = value._render_traceback_()\n","AttributeError: 'TypeError' object has no attribute '_render_traceback_'\n","\n","During handling of the above exception, another exception occurred:\n","\n","Traceback (most recent call last):\n","  File \"/usr/local/lib/python3.10/dist-packages/IPython/core/ultratb.py\", line 1101, in get_records\n","    return _fixed_getinnerframes(etb, number_of_lines_of_context, tb_offset)\n","  File \"/usr/local/lib/python3.10/dist-packages/IPython/core/ultratb.py\", line 248, in wrapped\n","    return f(*args, **kwargs)\n","  File \"/usr/local/lib/python3.10/dist-packages/IPython/core/ultratb.py\", line 281, in _fixed_getinnerframes\n","    records = fix_frame_records_filenames(inspect.getinnerframes(etb, context))\n","  File \"/usr/lib/python3.10/inspect.py\", line 1662, in getinnerframes\n","    frameinfo = (tb.tb_frame,) + getframeinfo(tb, context)\n","  File \"/usr/lib/python3.10/inspect.py\", line 1620, in getframeinfo\n","    filename = getsourcefile(frame) or getfile(frame)\n","  File \"/usr/lib/python3.10/inspect.py\", line 829, in getsourcefile\n","    module = getmodule(object, filename)\n","  File \"/usr/lib/python3.10/inspect.py\", line 861, in getmodule\n","    file = getabsfile(object, _filename)\n","  File \"/usr/lib/python3.10/inspect.py\", line 845, in getabsfile\n","    return os.path.normcase(os.path.abspath(_filename))\n","  File \"/usr/lib/python3.10/posixpath.py\", line 384, in abspath\n","    cwd = os.getcwd()\n","OSError: [Errno 107] Transport endpoint is not connected\n"]}],"source":["torch.__version__"]},{"cell_type":"code","execution_count":null,"metadata":{"colab":{"background_save":true},"id":"TuI-DWQjuJaV"},"outputs":[],"source":[]}],"metadata":{"accelerator":"GPU","colab":{"machine_shape":"hm","name":"","version":""},"gpuClass":"premium","interpreter":{"hash":"5b193160d7cc1e01522e5642bc36993162f6c79445953eacfe5d439a85308880"},"kernelspec":{"display_name":"Python 3.8.12 64-bit ('pytorch_m1': conda)","language":"python","name":"python3"},"language_info":{"codemirror_mode":{"name":"ipython","version":3},"file_extension":".py","mimetype":"text/x-python","name":"python","nbconvert_exporter":"python","pygments_lexer":"ipython3","version":"3.8.12"}},"nbformat":4,"nbformat_minor":0}